<?xml version="1.0" ?> <!-- =================================================================================== --> <!-- |    This document was autogenerated by xacro from /home/mriera/dev_ws/ros2_meca500_ws/install/meca500_description/share/meca500_description/urdf/meca500.urdf.xacro | --> <!-- |    EDITING THIS FILE BY HAND IS NOT RECOMMENDED                                 | --> <!-- =================================================================================== --> <robot name="Meca500_R4"> <link name="world"/> <material name="grey"> <color rgba="0.2 0.2 0.2 1.0"/> </material> <joint name="world_to_base_link" type="fixed"> <origin rpy="0 0 0" xyz="0 0 0"/> <parent link="world"/> <child link="base_link"/> </joint> <link name="base_link"> <visual> <origin rpy="0 0 0" xyz="0 0 0"/> <geometry> <mesh filename="package://meca500_description/meshes/link_0.dae"/> </geometry> <material name="grey"/> </visual> <collision> <origin rpy="0 0 0" xyz="0 0 0.05"/> <geometry> <cylinder length="0.105" radius="0.045"/> </geometry> </collision> <collision> <origin rpy="0 0 0" xyz="-0.0125 0 0.03"/> <geometry> <box size="0.115 0.090 0.06"/> </geometry> </collision> </link> <joint name="meca_axis_1" type="revolute"> <parent link="base_link"/> <child link="link_1"/> <origin rpy="0 0 0" xyz="0 0 0.135"/> <axis xyz="0 0 1"/> <limit effort="8.4" lower="-3.05" upper="3.05" velocity="3.926"/> </joint> <link name="link_1"> <visual> <origin rpy="0 0 0" xyz="0 0 0"/> <geometry> <mesh filename="package://meca500_description/meshes/link_1.dae"/> </geometry> <material name="grey"/> </visual> <inertial> <origin rpy="0 0 0" xyz="-0.00002037431904 0.002013004158 -0.02297639135"/> <mass value="0.5431025133"/> <inertia ixx="0.000915685257" ixy="5.49E-07" ixz="4.28E-07" iyy="0.0005022985235" iyz="0.00002704049297" izz="0.0008332485299"/> </inertial> <collision> <origin rpy="0 0 0" xyz="0 0 -0.005"/> <geometry> <box size="0.065 0.1 0.08"/> </geometry> </collision> </link> <joint name="meca_axis_2" type="revolute"> <parent link="link_1"/> <child link="link_2"/> <origin rpy="0 0 0" xyz="0 0 0"/> <axis xyz="0 1 0"/> <limit effort="8.4" lower="-1.22" upper="1.57" velocity="3.926"/> </joint> <link name="link_2"> <visual> <origin rpy="0 0 0" xyz="0 0 0"/> <geometry> <mesh filename="package://meca500_description/meshes/link_2.dae"/> </geometry> <material name="grey"/> </visual> <inertial> <origin rpy="1.57 -1.57 0" xyz="-0.005076026623 0.006334754388 0.04691754408"/> <mass value="1.209363494"/> <inertia ixx="0.001457420783" ixy="0.00009498376543" ixz="0.00001941186918" iyy="0.003988341228" iyz="0.00001173538506" izz="0.003332374168"/> </inertial> <collision> <origin rpy="0 -0.23 0" xyz="-0.005 0 0.025"/> <geometry> <box size="0.067 0.065 0.11"/> </geometry> </collision> <collision> <origin rpy="0 0.18 0" xyz="-0.007 0 0.10"/> <geometry> <box size="0.06 0.1 0.13"/> </geometry> </collision> </link> <joint name="meca_axis_3" type="revolute"> <parent link="link_2"/> <child link="link_3"/> <origin rpy="0 0 0" xyz="0 0 0.135"/> <axis xyz="0 1 0"/> <limit effort="8.4" lower="-2.35" upper="1.22" velocity="3.926"/> </joint> <link name="link_3"> <visual> <origin rpy="0 0 0" xyz="0 0 0"/> <geometry> <mesh filename="package://meca500_description/meshes/link_3.dae"/> </geometry> <material name="grey"/> </visual> <inertial> <origin rpy="1.57 0 0" xyz=" 0.009862786694 0.00343262302 0.01508651673"/> <mass value="0.8980717937"/> <inertia ixx="0.0006999643903" ixy="-0.0001856385329" ixz="0.00005438767026" iyy="0.0008589980073" iyz="0.00003237561764" izz="0.00103125794"/> </inertial> <collision> <origin rpy="0 0 0" xyz="0.017 0 0.03"/> <geometry> <box size="0.09 0.045 0.065"/> </geometry> </collision> <collision> <origin rpy="0 0 0" xyz="0 0 -0.006"/> <geometry> <box size="0.06 0.065 0.07"/> </geometry> </collision> </link> <joint name="meca_axis_4" type="revolute"> <parent link="link_3"/> <child link="link_4"/> <origin rpy="0 1.5708 0" xyz="0 0 0.038"/> <axis xyz="0 0 1"/> <limit effort="1.25" lower="-2.96" upper="2.96" velocity="6.108"/> </joint> <link name="link_4"> <visual> <origin rpy="0 0 3.14159265" xyz="0 0 0.120"/> <geometry> <mesh filename="package://meca500_description/meshes/link_4.dae"/> </geometry> <material name="grey"/> </visual> <inertial> <origin rpy="0 0 3.1415" xyz="0.00006098710044 0.00224976832 0.08976460875"/> <mass value="0.2093565436"/> <inertia ixx="0.0002307486811" ixy="-2.55E-07" ixz="-1.76E-07" iyy="0.0001528092348" iyz="-0.00001834894489" izz="0.0001573266858"/> </inertial> <collision> <origin rpy="0 0 0" xyz="0 0 0.1025"/> <geometry> <box size="0.045 0.075 0.08"/> </geometry> </collision> </link> <joint name="meca_axis_5" type="revolute"> <parent link="link_4"/> <child link="link_5"/> <origin rpy="0 0 0" xyz="0 0 0.120"/> <axis xyz="0 1 0"/> <limit effort="1.25" lower="-2.00" upper="2.00" velocity="6.108"/> </joint> <link name="link_5"> <visual> <origin rpy="0 0 0" xyz="0 0 0"/> <geometry> <mesh filename="package://meca500_description/meshes/link_5.dae"/> </geometry> <material name="grey"/> </visual> <inertial> <origin rpy="1.57 0 3.1415" xyz="0.0000355330703 0.003727390331 0.02216669127"/> <mass value="0.4881954861"/> <inertia ixx="0.0004368686961" ixy="8.60E-07" ixz="-3.41E-07" iyy="0.0001588423228" iyz="0.00002942257626" izz="0.0004066877932"/> </inertial> <collision> <origin rpy="0 0 0" xyz="0 0 0.02"/> <geometry> <box size="0.045 0.047 0.08"/> </geometry> </collision> </link> <joint name="meca_axis_6" type="revolute"> <parent link="link_5"/> <child link="link_6"/> <origin rpy="0 0 0" xyz="0 0 0.070"/> <axis xyz="0 0 1"/> <limit effort="0.75" lower="-6.28" upper="6.28" velocity="8.726"/> </joint> <link name="link_6"> <visual> <origin rpy="0 0 0" xyz="0 0 0"/> <geometry> <mesh filename="package://meca500_description/meshes/link_6.dae"/> </geometry> <material name="grey"/> </visual> <inertial> <origin rpy="0 0 0" xyz="0 0 0"/> <mass value="0"/> <inertia ixx="0" ixy="0" ixz="0" iyy="0" iyz="0" izz="0"/> </inertial> <collision> <origin rpy="0 0 0" xyz="0 0 -0.01"/> <geometry> <cylinder length="0.02" radius="0.015"/> </geometry> </collision> </link> <ros2_control name="Meca500System" type="system"> <hardware> <plugin>meca500_hardware/Meca500SystemHardware</plugin> <param name="robot_ip">192.168.0.100</param> </hardware> <joint name="meca_axis_1"> <command_interface name="velocity"> <param name="min">-2.61</param> <param name="max">2.61</param> </command_interface> <state_interface name="position"/> <state_interface name="velocity"/> </joint> <joint name="meca_axis_2"> <command_interface name="velocity"> <param name="min">-2.61</param> <param name="max">2.61</param> </command_interface> <state_interface name="position"/> <state_interface name="velocity"/> </joint> <joint name="meca_axis_3"> <command_interface name="velocity"> <param name="min">-3.14</param> <param name="max">3.14</param> </command_interface> <state_interface name="position"/> <state_interface name="velocity"/> </joint> <joint name="meca_axis_4"> <command_interface name="velocity"> <param name="min">-5.23</param> <param name="max">5.23</param> </command_interface> <state_interface name="position"/> <state_interface name="velocity"/> </joint> <joint name="meca_axis_5"> <command_interface name="velocity"> <param name="min">-5.23</param> <param name="max">5.23</param> </command_interface> <state_interface name="position"/> <state_interface name="velocity"/> </joint> <joint name="meca_axis_6"> <command_interface name="velocity"> <param name="min">-8.72</param> <param name="max">8.72</param> </command_interface> <state_interface name="position"/> <state_interface name="velocity"/> </joint> </ros2_control> </robot>